tests/data/backtest_twap_basic.csv
ts_ns,seq,action,order_id,side,type,price,qty,tif,new_price,new_qty,notes
100,1,NEW,10,SELL,LIMIT,100.0000,10,GTC,,,
101,1,NEW,11,SELL,LIMIT,101.0000,10,GTC,,,
102,1,NEW,12,BUY,LIMIT,99.0000,10,GTC,,,
110,1,NEW,13,SELL,LIMIT,100.5000,10,GTC,,,
120,1,NEW,14,SELL,LIMIT,100.2000,10,GTC,,,
125,1,NEW,15,SELL,MARKET,,1,IOC,,,
130,1,CANCEL,10,,,,,,,,
